Workbook

Sheet BİNA BİLGİLERİ
A1: HAFİF ÇELİK FİYAT HESAPLAMA ROBOTU
A2: Bina Alanı | B2: 105 | C2: DIŞ DUVAR KALINLIĞI | E2: İÇ DUVAR KALINLIĞI
A3: Tahmini kg/m² | B3: 32 | C3: 80 | E3: 80
A4: Bina Köşe Sayısı | B4: 6
A5: Zemin Kat En
A6: Zemin Kat Boy
A7: Kat Adeti | B7: 1
A8: Ara Kat Alanı
A9: Kat Yüksekliği | B9: 2.8
A10: Çatı Tipi | B10: BEŞİK
A11: Çatı Eğimi | B11: 0.3
A12: Toplam Çatı Oturum Alanı | B12: 105
A13: Çatı Kaplaması | B13: METAL KİREMİT ÇATI
A14: Aşık & Omega Sistemi / Tavan Paneli Çatı Paneli | B14: PANEL SİSTEM | C14: AŞIK ADETİ L:3000 | E14: OMEGA ADETİ L : 2500
A16: Saçak Genişliği (mt) | B16: 0.4
A17: Saçak Uzunluğu (mt) | B17: =10.28+10.28 -> 20.56
A18: Bina Alın Uzunluğu (mt) | B18: =10.2+10.2 -> 20.4
A20: ÖZEL BÜKÜM AKSESUAR | B20: MİKTAR | F20: BİRİM
A21: Sırt Mahya | F21: L:2500 / Ad.
A22: Parapet Kaplama Showroom | F22: L:2500 / Ad.
A23: Metal Kiremit Mahyası | B23: 4 | F23: L:2500 / Ad.
A24: Özel Mahya (Dar) | F24: L:2500 / Ad.
A25: Özel Mahya (Geniş) | F25: L:2500 / Ad.
A26: Metal Tahta | F26: L:2500 / Ad.
A28: KAPLAMA | B28: MİKTAR | F28: BİRİM
A29: Duvar Islak Hacim | B29: =17.5 -> 17.5 | F29: mt
A30: Tavan Islak Hacim | B30: =7+1.5+11 -> 19.5 | F30: m²
B31: DUVAR UZUNLUĞU | C31: BİRİM | D31: KAPLAMA-1 | E31: KAPLAMA-2 | F31: KAPLAMA-3
A32: Dış Duvar Kaplaması | B32: 39.5 | C32: mt | D32: 11 mm OSB 2 | E32: NEM BARİYERİ | F32: BORDEX
A33: İç Duvar Kaplaması | B33: 33 | C33: mt | D33: 11 mm OSB 2 | E33: NEM BARİYERİ | F33: ALÇIPAN
A34: Çatı Kaplaması | B34: =İSİMLENDİRME!S17 -> 126.7249 | C34: m² | D34: 11 mm OSB 2 | E34: NEM BARİYERİ
A35: Tavan Kaplaması | B35: 97 | C35: m² | D35: ALÇIPAN
A36: Saçak Altı Kaplama | B36: =B16*(B17+B18) -> 16.384 | C36: mt
A38: KAPI TÜRÜ | B38: ADET
A39: Çelik Kapı (90*205) | B39: 1
A40: PVC Kapı (90*200)
A41: Duble PVC Kapı (160*200)
A42: Melamin Kapı (90*201) | B42: 6
A43: Ahşap Kasalı Amerikan Kapı (90*201)
A45: PENCERE TÜRÜ | B45: ADET | C45: RENK
...

Sheet TEKLİF
A1: ZMT PREFABRİK Hafif Çelik Bina Yükleme Listesi | C1: DÜZENLENME TARİHİ | D1: 46195 | E1: ÇELİK | F1: DIŞ:140'LIK İÇ : 80'LİK | G1: DOLAR KURU | H1: TON FİYATI | I1: KDVSİZ FİYATLAR | K1: KDV DAHİL FİYATLAR | L1: İSKONTOLU FİYAT | M1: BRÜT KAR | N1: S SERİ TON FİYATI | O1: GALVANİZ FİYATI | P1: BOYALI SAÇ FİYATI
A2: FİRMA: | E2: Alan (m²) | G2: 48.1 | H2: 1.3 | N2: 1.35 | O2: 0.9 | P2: 1.05
A3: Müşteri Adı: | E3: H:Yükseklik | F3: 2800
A4: Teklif Sayımı Yapan: | E4: Tarih
A5: Proje Kontrolü Yapan: | E5: Tarih
A6: Üretim Listesi Yapan: | E6: Tarih
A7: Proje Aşaması | E7: CRM NO
B8: Malzeme | C8: Malzeme Ölçüsü | D8: Adet | E8: Birim Fiyatı | F8: TOPLAM | I8: TOPLAM | J8: TOPLAM | K8: TOPLAM | L8: TOPLAM | M8: TOPLAM
A9: HAFİF ÇELİK PANEL VE METAL AKSAM GRUBU | D9: 1001
A10: 1 | B10: HAFİF ÇELİK PANEL KARKAS HALİNDE | C10: KG | D10: ='BİNA BİLGİLERİ'!B2*'BİNA BİLGİLERİ'!B3 -> 3360 | E10: =H2*G2*1.6 -> 100.048 | F10: =D10*E10 -> 336161.28 | I10: =G2*O2 -> 43.29 | J10: =I10*D10 -> 145454.4 | K10: =I10*1.2 -> 51.948 | L10: =E10-E10*$E$223/100 -> 75.036 | M10: =(L10-K10)/K10 -> 0.44444444
D11: Z1
A12: 2 | B12: ÖZEL BÜKÜM SAÇAK ALIN SACI (GALVANİZ) | C12: 250*2500 | D12: =IF('BİNA BİLGİLERİ'!B14="AŞIK OMEGA",ROUNDUP('BİNA BİLGİLERİ'!B17/2.5,0),0) -> 0 | E12: =K12*1.73 -> 647.96299 | F12: =E12*D12 -> 0 | I12: =7.21*O2*G2 -> 312.1209 | J12: =I12*D12 -> 0 | K12: =I12*1.2 -> 374.54508 | L12: =E12-E12*$E$223/100 -> 485.97224 | M12: =(L12-K12)/K12 -> 0.2975
A13: 3 | B13: ÖZEL BÜKÜM ALIN SACI | C13: 120*2800 | D13: =IF('BİNA BİLGİLERİ'!B14="AŞIK OMEGA",ROUNDUP('BİNA BİLGİLERİ'!B18/2.5,0),0) -> 0 | E13: =K13*1.73 -> 220.1816 | F13: =E13*D13 -> 0 | I13: =2.1*P2*$G$2 -> 106.0605 | J13: =I13*D13 -> 0 | K13: =I13*1.2 -> 127.2726 | L13: =E13-E13*$E$223/100 -> 165.1362 | M13: =(L13-K13)/K13 -> 0.2975
A14: 4 | B14: AŞIK KAPAMA U'SU (GALVANİZ) | C14: 80*2500 | D14: =IF('BİNA BİLGİLERİ'!B14="AŞIK OMEGA",ROUNDUP('BİNA BİLGİLERİ'!B18/2.5,0),0) -> 0 | E14: =K14*1.73 -> 197.71409 | F14: =E14*D14 -> 0 | I14: =2.2*O2*G2 -> 95.238 | J14: =I14*D14 -> 0 | K14: =I14*1.2 -> 114.2856 | L14: =E14-E14*$E$223/100 -> 148.28557 | M14: =(L14-K14)/K14 -> 0.2975
D15: Z1
A16: 5 | B16: KÖŞEBENT | C16: 30*30*2500 | D16: =IF('BİNA BİLGİLERİ'!B2<50,3,IF('BİNA BİLGİLERİ'!B2<150,5,IF('BİNA BİLGİLERİ'!B2<250,7,10))) -> 5 | E16: =K16*1.73 -> 84.657578 | F16: =E16*D16 -> 423.28789 | I16: =0.942*O2*G2 -> 40.77918 | J16: =I16*D16 -> 203.8959 | K16: =I16*1.2 -> 48.935016 | L16: =E16-E16*$E$223/100 -> 63.493183 | M16: =(L16-K16)/K16 -> 0.2975
A17: 6 | B17: KÖŞEBENT | C17: 50*50*2500 | D17: =IF('BİNA BİLGİLERİ'!B2<50,3,IF('BİNA BİLGİLERİ'!B2<150,5,IF('BİNA BİLGİLERİ'!B2<250,7,10))) -> 5 | E17: =K17*1.73 -> 141.09596 | F17: =E17*D17 -> 705.47981 | I17: =1.57*O2*G2 -> 67.9653 | J17: =I17*D17 -> 339.8265 | K17: =I17*1.2 -> 81.55836 | L17: =E17-E17*$E$223/100 -> 105.82197 | M17: =(L17-K17)/K17 -> 0.2975
A18: 7 | B18: ÖZEL AÇILI KÖŞEBENT 1,2 mm | C18: 100*100*2500 | E18: =K18*1.73 -> 359.48016 | F18: =E18*D18 -> 0 | I18: =4*O2*G2 -> 173.16 | J18: =I18*D18 -> 0 | K18: =I18*1.2 -> 207.792 | L18: =E18-E18*$E$223/100 -> 269.61012 | M18: =(L18-K18)/K18 -> 0.2975
D19: Z1
A20: 8 | B20: ANKALAJ AYAĞI | C20: 50x200 | D20: =ROUNDUP('BİNA BİLGİLERİ'!B32/2,0) -> 20 | E20: =K20*4 -> 168 | F20: =E20*D20 -> 3360 | I20: 35 | J20: =I20*D20 -> 700 | K20: =I20*1.2 -> 42 | L20: =E20-E20*$E$223/100 -> 126 | M20: =(L20-K20)/K20 -> 2
A21: 9 | B21: BİRLEŞİM APARATI | C21: 70x550 | E21: =K21*1.73 -> 319.704 | F21: =E21*D21 -> 0 | I21: 154 | J21: =I21*D21 -> 0 | K21: =I21*1.2 -> 184.8 | L21: =E21-E21*$E$223/100 -> 239.778 | M21: =(L21-K21)/K21 -> 0.2975
A22: 10 | B22: 100 LÜK PİS SU KAPAMASI (GALVANİZ) | C22: 180*2800 | D22: ='BİNA BİLGİLERİ'!C61 -> 0 | E22: =K22*1.73 -> 665.0383 | F22: =E22*D22 -> 0 | I22: =7.4*O2*G2 -> 320.346 | J22: =I22*D22 -> 0 | K22: =I22*1.2 -> 384.4152 | L22: =E22-E22*$E$223/100 -> 498.77872 | M22: =(L22-K22)/K22 -> 0.2975
D23: Z1
A24: 11 | B24: SIRT MAHYA | C24: L:2500 | D24: ='BİNA BİLGİLERİ'!B21 -> 0 | E24: =K24*1.73 -> 808.83036 | F24: =E24*D24 -> 0 | I24: =9*O2*$G$2 -> 389.61 | J24: =I24*D24 -> 0 | K24: =I24*1.2 -> 467.532 | L24: =E24-E24*$E$223/100 -> 606.62277 | M24: =(L24-K24)/K24 -> 0.2975
A25: 12 | B25: PARAPET KAPLAMA SHOWROOM | C25: L:2800 | D25: ='BİNA BİLGİLERİ'!B22 -> 0 | E25: =K25*1.73 -> 471.81771 | F25: =E25*D25 -> 0 | I25: =4.5*P2*$G$2 -> 227.2725 | J25: =I25*D25 -> 0 | K25: =I25*1.2 -> 272.727 | L25: =E25-E25*$E$223/100 -> 353.86328 | M25: =(L25-K25)/K25 -> 0.2975
A26: 13 | B26: METAL KİREMİT MAHYASI | C26: L:2800 | D26: ='BİNA BİLGİLERİ'!B23 -> 4 | E26: =K26*1.73 -> 529.48432 | F26: =E26*D26 -> 2117.9373 | I26: =5.05*P2*$G$2 -> 255.05025 | J26: =I26*D26 -> 1020.201 | K26: =I26*1.2 -> 306.0603 | L26: =E26-E26*$E$223/100 -> 397.11324 | M26: =(L26-K26)/K26 -> 0.2975
A27: 14 | B27: ÖZEL MAHYA (DAR OLAN) | C27: 10x1500 | D27: ='BİNA BİLGİLERİ'!B24 -> 0 | E27: =K27*1.73 -> 92.58112 | F27: =E27*D27 -> 0 | I27: =0.883*P2*$G$2 -> 44.595915 | J27: =I27*D27 -> 0 | K27: =I27*1.2 -> 53.515098 | L27: =E27-E27*$E$223/100 -> 69.43584 | M27: =(L27-K27)/K27 -> 0.2975
A28: 15 | B28: ÖZEL MAHYA (GENİŞ OLAN) | C28: 20x2800 | D28: ='BİNA BİLGİLERİ'!B25 -> 0 | E28: =K28*1.73 -> 314.54514 | F28: =E28*D28 -> 0 | I28: =3*P2*$G$2 -> 151.515 | J28: =I28*D28 -> 0 | K28: =I28*1.2 -> 181.818 | L28: =E28-E28*$E$223/100 -> 235.90886 | M28: =(L28-K28)/K28 -> 0.2975
A29: 16 | B29: METAL TAHTA | C29: L:2500 | D29: ='BİNA BİLGİLERİ'!B26 -> 0 | E29: =K29*1.73 -> 134.80506 | F29: =E29*D29 -> 0 | I29: =1.5*O2*$G$2 -> 64.935 | J29: =I29*D29 -> 0 | K29: =I29*1.2 -> 77.922 | L29: =E29-E29*$E$223/100 -> 101.10379 | M29: =(L29-K29)/K29 -> 0.2975
D30: Z1
A31: 17 | B31: 60'LIK DUVAR OMEGASI | C31: 60*2500 | D31: =ROUNDUP(IF('BİNA BİLGİLERİ'!B7=2,((('BİNA BİLGİLERİ'!B5/0.62)+1)*'BİNA BİLGİLERİ'!B6)/2.5,0)+IF('BİNA BİLGİLERİ'!B14="AŞIK OMEGA",'BİNA BİLGİLERİ'!D15,0),0) -> 0 | E31: =K31*1.73 -> 247.14261 | F31: =E31*D31 -> 0 | I31: =2.75*O2*$G$2 -> 119.0475 | J31: =I31*D31 -> 0 | K31: =I31*1.2 -> 142.857 | L31: =E31-E31*$E$223/100 -> 185.35696 | M31: =(L31-K31)/K31 -> 0.2975
A32: 18 | B32: 60'LIK DUVAR OMEGASI | C32: 60*3760 | E32: =K32*1.73 -> 370.26456 | F32: =E32*D32 -> 0 | I32: =4.12*O2*$G$2 -> 178.3548 | J32: =I32*D32 -> 0 | K32: =I32*1.2 -> 214.02576 | L32: =E32-E32*$E$223/100 -> 277.69842 | M32: =(L32-K32)/K32 -> 0.2975
A33: 19 | B33: 60'LIK DUVAR OMEGASI | C33: 60*5000 | E33: =K33*1.73 -> 494.28522 | F33: =E33*D33 -> 0 | I33: =5.5*O2*$G$2 -> 238.095 | J33: =I33*D33 -> 0 | K33: =I33*1.2 -> 285.714 | L33: =E33-E33*$E$223/100 -> 370.71391 | M33: =(L33-K33)/K33 -> 0.2975
D34: Z1
A35: 20 | B35: ÇATI AŞIK OMEGASI | C35: L:4200 | E35: =3.5*O2*1.2*$G$2*1.73 -> 314.54514 | F35: =E35*D35 -> 0 | I35: =3.5*O2*$G$2 -> 151.515 | J35: =I35*D35 -> 0 | K35: =I35*1.2 -> 181.818 | L35: =E35-E35*$E$223/100 -> 235.90885 | M35: =(L35-K35)/K35 -> 0.2975
A36: 21 | B36: ÇATI AŞIK OMEGASI | C36: L:3000 | D36: =IF('BİNA BİLGİLERİ'!B14="AŞIK OMEGA",'BİNA BİLGİLERİ'!C15,0) -> 0 | E36: =2.5*O2*1.2*$G$2*1.73 -> 224.6751 | F36: =E36*D36 -> 0 | I36: =2.5*O2*$G$2 -> 108.225 | J36: =I36*D36 -> 0 | K36: =I36*1.2 -> 129.87 | L36: =E36-E36*$E$223/100 -> 168.50633 | M36: =(L36-K36)/K36 -> 0.2975
D37: TOPLAM | F37: =SUM(F10:F36) -> 342767.98 | I37: =SUM(I10:I36) -> 3276.1758 | J37: =SUM(J10:J36) -> 147718.32 | K37: =SUM(K10:K36) -> 3931.411 | L37: =SUM(L10:L36) -> 5180.1443
A38: ALÇIPAN VE KAPLAMA GRUBU | D38: 1002
A39: 1 | B39: BEYAZ ALÇIPAN | C39: 12x1200x2500 | D39: =(ROUNDUP((IF('BİNA BİLGİLERİ'!D32="ALÇIPAN",1,0)+IF('BİNA BİLGİLERİ'!E32="ALÇIPAN",1,0)+IF('BİNA BİLGİLERİ'!F32="ALÇIPAN",1,0))*'BİNA BİLGİLERİ'!B32*'BİNA BİLGİLERİ'!B9/3,0)+(ROUNDUP((IF('BİNA BİLGİLERİ'!D33="ALÇIPAN",1,0)+IF('BİNA BİLGİLERİ'!E33="ALÇIPAN",1,0)+IF('BİNA BİLGİLERİ'!F33="ALÇIPAN",1,0))*'BİNA BİLGİLERİ'!B33*'BİNA BİLGİLERİ'!B9/3,0)*2)+ROUNDUP((IF('BİNA BİLGİLERİ'!D34="ALÇIPAN",1,0)+IF('BİNA BİLGİLERİ'!E34="ALÇIPAN",1,0)+IF('BİNA BİLGİLERİ'!F34="ALÇIPAN",1,0))*'BİNA BİLGİLERİ'!B34/3,0)+ROUNDUP((IF('BİNA BİLGİLERİ'!D35="ALÇIPAN",1,0)+IF('BİNA BİLGİLERİ'!E35="ALÇIPAN",1,0)+IF('BİNA BİLGİLERİ'!F35="ALÇIPAN",1,0))*'BİNA BİLGİLERİ'!B35/3,0)+ROUNDUP((IF('BİNA BİLGİLERİ'!D33="ALÇIPAN",1,0)+IF('BİNA BİLGİLERİ'!E33="ALÇIPAN",1,0)+IF('BİNA BİLGİLERİ'!F33="ALÇIPAN",1,0))*'BİNA BİLGİLERİ'!B32*'BİNA BİLGİLERİ'!B9/3,0))-D40 -> 108 | E39: =K39*1.73 -> 371.604 | F39: =E39*D39 -> 40133.232 | I39: 179 | J39: =I39*D39 -> 19332 | K39: =I39*1.2 -> 214.8 | L39: =E39-E39*$E$223/100 -> 278.703 | M39: =(L39-K39)/K39 -> 0.2975
A40: 2 | B40: YEŞİL ALÇIPAN | C40: 12x1200x2500 | D40: =ROUNDUP((IF('BİNA BİLGİLERİ'!D35="ALÇIPAN",1,0)+IF('BİNA BİLGİLERİ'!E35="ALÇIPAN",1,0)+IF('BİNA BİLGİLERİ'!F35="ALÇIPAN",1,0))*'BİNA BİLGİLERİ'!B30/3,0)+ROUNDUP((IF('BİNA BİLGİLERİ'!D33="ALÇIPAN",1,0)+IF('BİNA BİLGİLERİ'!E33="ALÇIPAN",1,0)+IF('BİNA BİLGİLERİ'!F33="ALÇIPAN",1,0))*('BİNA BİLGİLERİ'!B29*'BİNA BİLGİLERİ'!B9)/3,0) -> 24 | E40: =K40*1.73 -> 544.95 | F40: =E40*D40 -> 13078.8 | I40: =315/1.2 -> 262.5 | J40: =I40*D40 -> 6300 | K40: =I40*1.2 -> 315 | L40: =E40-E40*$E$223/100 -> 408.7125 | M40: =(L40-K40)/K40 -> 0.2975
...

Sheet İSİMLENDİRME
A1: VAR
A2: YOK
A10: BEYAZ
A11: ANTRASİT
A12: ALTINMEŞE
P17: ='BİNA BİLGİLERİ'!B11 -> 0.3 | Q17: =VLOOKUP(P17,P19:Q26,2,1) -> 1.044 | R17: ='BİNA BİLGİLERİ'!B12+'BİNA BİLGİLERİ'!B36 -> 121.384 | S17: =Q17*R17 -> 126.7249
P19: 0.25 | Q19: 1.0308
P20: 0.3 | Q20: 1.044
P21: 0.35 | Q21: 1.0595
P22: 0.4 | Q22: 1.077
P23: 0.45 | Q23: 1.0966
P24: 0.5 | Q24: 1.118
P25: 0.55 | Q25: 1.1413
P26: 0.6 | Q26: 1.1662
I28: 1
I29: 2
L32: KIRMA
L33: BEŞİK
A34: ALÇIPAN | L34: PARAPET | Z34: 8
A35: BORDEX | L35: TEK EĞİM | Z35: 16
A36: 11 mm OSB 2 | Z36: 12
A37: YALIBASKI SİDİNG FİBERCEMENT | Z37: 7
A38: AĞAÇDESEN FUGALI FİBERCEMENT | Z38: 5
A39: TAŞDESEN FUGALI FİBERCEMENT | G39: NEM BARİYERİ | Z39: 4
A40: AHŞAP DESEN LEVHA | G40: MEBRAN | O40: ZMT'YE AİT | Z40: 5
A41: FİBERCEMENT LEVHA | G41: ARDUAZLI MEBRAN | O41: MÜŞTERİYE AİT | Z41: 15
A42: NEM BARİYERİ | Z42: 1
A43: MEBRAN | Z43: 2
A44: ARDUAZLI MEBRAN | Z44: 1
A45: AŞIK OMEGA | G45: 80 | H45: 2 | Z45: 1
A46: PANEL SİSTEM | G46: 90 | H46: 2 | Z46: 5
G47: 140 | H47: 3 | Z47: 5
G48: 200 | H48: 4 | Z48: 3
G49: 300 | H49: 6 | Z49: 5
Z50: 5
Z51: 1
Z52: 5

Sheet FORMÜL
I9: DIŞ DUVAR M²
C10: TOPLAM M² | D10: ADET | E10: FİRELİ ADET SAYISI %3 | F10: YÜKLENECEK ADET | I10: BAŞ MAKAS M²
B11: FİBERCEMENT YALI BASKI | C11: =J9+J10+2*J11 -> 0 | D11: =C11/0.45 -> 0 | E11: =D11*1.03 -> 0 | F11: =ROUNDUP(E11,0) -> 0 | I11: DİREK SAYI*DİREK M²
B12: KNAUF PLUS(5CM)DIŞ | C12: =J9*2 -> 0 | D12: =C12/14.4 -> 0 | E12: =D12*1.03 -> 0 | F12: =ROUNDUP(E12,0) -> 0 | I12: DUVAR USTU ŞASE M²
B13: KNAUF PLUS (5CM) İÇ | C13: =J13+J15 -> 0 | D13: =C13/14.4 -> 0 | E13: =D13*1.03 -> 0 | F13: =ROUNDUP(E13,0) -> 0 | I13: İÇ DUVAR M²
B14: ALÇIPAN | C14: =2*J9+4*J13+J14+J15+J20 -> 0 | D14: =C14/3 -> 0 | E14: =D14*1.03 -> 0 | F14: =ROUNDUP(E14,0)-F19 -> 0 | I14: TAVAN M²
B15: FİBERCEMENT 8mm | C15: =J9+J10+J11+J12+J21 -> 0 | D15: =C15/10 -> 0 | E15: =D15*1.03 -> 0 | F15: =ROUNDUP(E15,0) -> 0 | I15: ŞASE M²
B16: Knauf Çatı Şiltesi | C16: =J24 -> 0 | D16: =C16/9.6 -> 0 | E16: =D16*1.03 -> 0 | F16: =ROUNDUP(E16,0) -> 0 | I16: ÇATI M² / OSB İÇİN
B17: OSB Dış Duvar + Çatı | C17: =J9+J10+J11+J12+J16 -> 0 | D17: =C17/2.97 -> 0 | E17: =D17*1.03 -> 0 | F17: =ROUNDUP(E17,0) -> 0 | I17: BACA M²
B18: OSB ÇATI SADECE | C18: =J16 -> 0 | D18: =C18/2.97 -> 0 | E18: =D18*1.03 -> 0 | F18: =ROUNDUP(E18,0) -> 0 | I18: YEŞİL ALÇIPAN M²
B19: YEŞİL ALÇIPAN | C19: =(J18) -> 0 | D19: =C19/3 -> 0 | E19: =D19*1.03 -> 0 | F19: =ROUNDUP(E19,0) -> 0 | I19: MERDİVEN
B20: FİBERCEMENT LAMBA ZIVANA | C20: =J9+J10+2*J11+J12 -> 0 | D20: =C20/1.025 -> 0 | E20: =D20*1.07 -> 0 | F20: =ROUNDUP(E20,0) -> 0 | I20: MERDİVEN ALTI
B21: BETOPAN 16mm | C21: =(J15+J19) -> 0 | D21: =C21/3.125 -> 0 | E21: =D21*1.03 -> 0 | F21: =ROUNDUP(E21,0) -> 0 | I21: SAÇAK KAPAMA MT
B22: SAÇAK ALIN UZUNLUK | C22: =(J22) -> 0 | D22: =C22/2.5 -> 0 | E22: =D22*1.01 -> 0 | F22: =ROUNDUP(E22,0) -> 0 | I22: SAÇAK ALIN UZUNLUK
B23: BORDEX ( Plaka ) | C23: =J9+J10+J11+J12 -> 0 | D23: =C23/2.88 -> 0 | E23: =D23*1.03 -> 0 | F23: =ROUNDUP(E23,0) -> 0 | I23: BACA
I24: BİNA M²
